Workbook

Sheet 编者的话
A1: 车友们好，这里是狂野飙车9国服数据表！ 由于本表还有很多不完善的地方，所以邀请各位读者一起制作本表！ 如何为编辑表格做贡献 表格中红色的区域是错误的数据 黄色的区域是存疑的数据 如果你知道红色区域的准确值，请通过添加批注的方式告诉我们哟。 绿色的区域是经过确认的数据（也说不定有错误！） 蓝色的区域是经过遐想的数据。 如何为完善数据做贡献 1，留意你的车辆改装时的改装费用，和零件数量 2，留意你的车辆升星时的图纸数量 3，其他各种手段渠道获得的数据。 数据来源与感谢 本表格参考了硫化镉（国际服）的表格（https://www.bilibili.com/read/cv5556876） 车辆性能数据以国际服为准（并且考虑到了国服还未采用的国际服的平衡性调整！） 还要感谢表格制作人员，为数据做出贡献的小伙伴，和各位读者车友！

Sheet 全车数据表
B1: 车辆信息 | I1: 国际服 | J1: 满改数据 | O1: 满改氮效 | P1: 图纸 | X1: 金币改装（单项） | AM1: 零件改装（单项） | AW1: 速度加成 | AZ1: 车库等级卡牌包 | BA1: 获取方式 | BB1: 获取途径 | BO1: 特性
A2: 序号 | C2: 别名 | D2: 厂商 | E2: 代号 | F2: 级别 | G2: 星级 | H2: 版本 | I2: 性能分 | J2: 性能分 | K2: 极速 | L2: 加速 | M2: 操控 | N2: 氮气 | O2: 单喷时间 | P2: 品质 | Q2: 解锁 | R2: 二星 | S2: 三星 | T2: 四星 | U2: 五星 | V2: 六星 | W2: 总计 | X2: 1 | Y2: 2 | Z2: 3 | AA2: 4 | AB2: 5 | AC2: 6 | AD2: 7 | AE2: 8 | AF2: 9 | AG2: 10 | AH2: 11 | AI2: 12 | AJ2: 13 | AK2: 14 | AL2: 四项总计 | AM2: 蓝色零件 | AN2: 数量 | AO2: 紫色零件 | AP2: 数量 | AQ2: 金色零件 | AR2: 数量 | AS2: 史诗零件 | AT2: 数量 | AU2: 四项总计 | AV2: MAX费用 | AW2: 氮速 | AX2: 蓝速 | AY2: 空速 | BB2: 战利品 | BC2: 每日任务 | BD2: 级别杯 | BE2: 传奇商店 | BF2: 独家赛事 | BG2: 寻车 | BH2: 通行证 | BI2: 惊艳亮相 | BJ2: 经典多人 | BK2: 1V1多人 | BL2: 特殊赛事 | BM2: 大奖赛 | BN2: 联会赛事 | BO2: 钥匙 | BP2: 贴纸 | BQ2: 独占贴纸 | BR2: 外观套件 | BS2: 敞篷 | BT2: 氮气特效 | BU2: 商店金卡 | BV2: 关键词 | BW2: 图纸数量 | BX2: 精英赛 | BY2: 狂野大师 | BZ2: 大师条件
A3: 1 | B3: Mitsubishi Lancer Evolution | C3: 三菱 | D3: Mitsubishi | E3: lancer | F3: D | G3: ★★★ | H3: 1.3 | I3: 1381 | J3: 1381 | K3: 270.1 | L3: 55.03 | M3: 53.79 | N3: 68.19 | O3: 10.75 | P3: 特殊 | Q3: 5 | R3: 8 | S3: 30 | W3: 43 | X3: 4850 | Y3: 5200 | Z3: 5600 | AA3: 6200 | AB3: 6900 | AC3: 10500 | AD3: 14500 | AE3: 22000 | AF3: 28000 | AG3: 36000 | AL3: 559000 | AM3: 5000 | AN3: 5 | AO3: 10000 | AP3: 1 | AU3: 140000 | AV3: 699000 | AW3: 282 | AY3: 363 | AZ3: 1 | BA3: 级别杯 | BD3: 1 | BE3: 1 | BR3: 1 | BV3: 天赐三菱 | BY3: 1 | BZ3: 4
A4: 2 | B4: BMW Z4 LCI E89 | C4: Z4 | D4: BMW | E4: z4 | F4: D | G4: ★★★ | H4: 1.3 | I4: 1476 | J4: 1476 | K4: 266.8 | L4: 68.86 | M4: 47.43 | N4: 57.49 | O4: 7.466 | P4: 特殊 | Q4: 5 | R4: 8 | S4: 45 | W4: 58 | X4: 4850 | Y4: 5200 | Z4: 5600 | AA4: 6200 | AB4: 6900 | AC4: 10500 | AD4: 14500 | AE4: 22000 | AF4: 28000 | AG4: 35000 | AL4: 555000 | AM4: 5000 | AN4: 5 | AO4: 10000 | AP4: 1 | AU4: 140000 | AV4: 695000 | AW4: 278 | AY4: 359 | AZ4: 1 | BA4: 级别杯 | BD4: 1 | BE4: 1 | BS4: 可开合 | BV4: 宝马 | BY4: 1 | BZ4: 4
A5: 3 | B5: Chevrolet Camaro LT | C5: LT | D5: Chevrolet | E5: lt | F5: D | G5: ★★★ | H5: 1.3 | I5: 1546 | J5: 1546 | K5: 284.1 | L5: 64.81 | M5: 48.39 | N5: 63.29 | O5: 8.249 | P5: 特殊 | Q5: 5 | R5: 12 | S5: 30 | W5: 47 | X5: 4850 | Y5: 5200 | Z5: 5600 | AA5: 6200 | AB5: 6900 | AC5: 10500 | AD5: 14500 | AE5: 22000 | AF5: 28000 | AG5: 35000 | AL5: 555000 | AM5: 5000 | AN5: 5 | AO5: 10000 | AP5: 1 | AU5: 140000 | AV5: 695000 | AW5: 296 | AY5: 380 | AZ5: 1 | BA5: 级别杯 | BB5: 1 | BD5: 1 | BE5: 1 | BV5: 雪佛兰科迈罗 | BY5: 1 | BZ5: 4
A6: 4 | B6: Nissan 370Z Nismo | C6: 370 | D6: Nissan | E6: 370 | F6: D | G6: ★★★ | H6: 1.3 | I6: 1662 | J6: 1662 | K6: 268.5 | L6: 66.61 | M6: 81.83 | N6: 67.07 | O6: 10.35 | P6: 特殊 | Q6: 10 | R6: 12 | S6: 30 | W6: 52 | X6: 4000 | Y6: 5000 | Z6: 5500 | AA6: 6000 | AB6: 7000 | AC6: 10000 | AD6: 15000 | AE6: 22000 | AF6: 28000 | AG6: 36000 | AL6: 554000 | AM6: 5000 | AN6: 5 | AO6: 10000 | AP6: 1 | AU6: 140000 | AV6: 694000 | AW6: 280 | AY6: 361 | AZ6: 1 | BA6: 级别杯 | BB6: 1 | BD6: 1 | BE6: 1 | BV6: 日产 尼桑 | BY6: 1 | BZ6: 4
A7: 5 | B7: Dodge Challenger SRT8 | C7: srt8 | D7: Dodge | E7: srt8 | F7: D | G7: ★★★ | H7: 1.3 | I7: 1687 | J7: 1683 | K7: 308.4 | L7: 71.92 | M7: 37.98 | N7: 45.41 | O7: 5.05 | P7: 特殊 | Q7: 15 | R7: 20 | S7: 30 | W7: 65 | X7: 4000 | Y7: 5000 | Z7: 5500 | AA7: 6000 | AB7: 7000 | AC7: 10000 | AD7: 15000 | AE7: 22000 | AF7: 28000 | AG7: 36000 | AL7: 554000 | AM7: 5000 | AN7: 5 | AO7: 10000 | AP7: 1 | AU7: 140000 | AV7: 694000 | AW7: 321 | AY7: 410 | AZ7: 1 | BA7: 级别杯 | BD7: 1 | BE7: 1 | BV7: 道奇 挑战者 送人头 e霸 | BY7: 1 | BZ7: 4
A8: 6 | B8: KTM X-Bow GTX | C8: GTX | D8: KTM | E8: gtx | F8: D | G8: ★★★ | H8: 4.1 | I8: 1738 | J8: 1738 | K8: 247.5 | L8: 83.84 | M8: 64.99 | N8: 66.99 | P8: 特殊 | Q8: 20 | R8: 25 | S8: 30 | W8: 75 | X8: 6000 | Y8: 6500 | Z8: 7000 | AA8: 8000 | AB8: 9000 | AC8: 14000 | AD8: 19000 | AE8: 29000 | AF8: 36500 | AG8: 46000 | AL8: 724000 | AM8: 6000 | AN8: 5 | AO8: 12000 | AP8: 1 | AU8: 168000 | AV8: 892000 | AW8: 258 | AX8: 274 | AY8: 350 | BA8: 周末爆冲
A9: 7 | B9: Volkswagen XL Sport Concept | C9: 大众 | D9: Volkswagen | E9: xl | F9: D | G9: ★★★ | H9: 1.3 | I9: 1814 | J9: 1814 | K9: 291.2 | L9: 60.31 | M9: 62.02 | N9: 61.94 | O9: 7.65 | P9: 特殊 | Q9: 15 | R9: 20 | S9: 30 | W9: 65 | X9: 6350 | Y9: 6800 | Z9: 7300 | AA9: 8200 | AB9: 9100 | AC9: 13500 | AD9: 19000 | AE9: 29000 | AF9: 36500 | AG9: 46000 | AL9: 727000 | AM9: 7500 | AN9: 5 | AO9: 15000 | AP9: 1 | AU9: 210000 | AV9: 937000 | AW9: 303 | AY9: 389 | AZ9: 1 | BA9: 级别杯 | BD9: 1 | BE9: 1 | BV9: 大众
A10: 8 | B10: BMW 3.0 CSL Hommage | C10: 宝马3.0 | D10: BMW | E10: hommage | F10: D | G10: ★★★ | H10: 1.3 | I10: 1826 | J10: 1827 | K10: 297.5 | L10: 73.39 | M10: 50.08 | N10: 51.2 | O10: 5.782 | P10: 特殊 | Q10: 20 | R10: 20 | S10: 30 | W10: 70 | X10: 6350 | Y10: 6800 | Z10: 7300 | AA10: 8200 | AB10: 9100 | AC10: 13500 | AD10: 19000 | AE10: 29000 | AF10: 36500 | AG10: 46000 | AL10: 727000 | AM10: 7500 | AN10: 5 | AO10: 15000 | AP10: 1 | AU10: 210000 | AV10: 937000 | AW10: 310 | AY10: 396 | AZ10: 1 | BA10: 级别杯 | BD10: 1 | BE10: 1 | BV10: 宝马 | BY10: 1 | BZ10: 4
A11: 9 | B11: Chevrolet Camaro ZL1 50TH Edition | C11: 50th | D11: Chevrolet | E11: 50th | F11: D | G11: ★★★ | H11: 1.3 | I11: 1971 | J11: 1971 | K11: 272.1 | L11: 78.14 | M11: 83.14 | N11: 72.33 | O11: 13.016 | P11: 特殊 | Q11: 20 | R11: 20 | S11: 30 | W11: 70 | X11: 7500 | Y11: 10000 | Z11: 11000 | AA11: 12000 | AB11: 15000 | AC11: 20000 | AD11: 28000 | AE11: 43000 | AF11: 55000 | AG11: 69000 | AL11: 1082000 | AM11: 7500 | AN11: 5 | AO11: 15000 | AP11: 1 | AU11: 210000 | AV11: 1292000 | AW11: 284 | AY11: 365 | AZ11: 8 | BA11: 传奇商店 | BE11: 1 | BQ11: 1款 | BR11: 1 | BV11: 雪佛兰 科迈罗 | BX11: 1
A12: 10 | B12: DS Automobiles DS E-Tense | C12: DS | D12: DS Automobiles | E12: ds | F12: D | G12: ★★★ | H12: 1.3 | I12: 1976 | J12: 1976 | K12: 270.1 | L12: 76.07 | M12: 81.27 | N12: 72.3 | O12: 13.1 | P12: 特殊 | Q12: 20 | R12: 25 | S12: 30 | W12: 75 | AM12: 7500 | AN12: 5 | AO12: 15000 | AP12: 1 | AU12: 210000 | AW12: 282 | AY12: 363 | AZ12: 8 | BA12: 级别杯 | BQ12: 2022虎年春节 | BV12: 屌丝龙 | BX12: 1
A13: 11 | B13: Porsche Boxster 25th | C13: Boxster | D13: Porsche | E13: boxster | F13: D | G13: ★★★★ | H13: 3.9 | I13: 1844 | J13: 1985 | K13: 298.7 | L13: 72.12 | M13: 46.1 | N13: 54.35 | P13: 稀有 | Q13: 20 | R13: 30 | S13: 41 | T13: 45 | W13: 136 | X13: 7500 | Y13: 10000 | Z13: 14000 | AA13: 18000 | AB13: 26000 | AC13: 35000 | AD13: 50000 | AE13: 61000 | AF13: 68000 | AG13: 73000 | AH13: 77000 | AL13: 1758000 | AM13: 16500 | AN13: 7 | AO13: 33000 | AP13: 2 | AQ13: 99000 | AR13: 1 | AU13: 1122000 | AV13: 2880000 | AW13: 311 | AY13: 398 | BA13: 周末爆冲 | BG13: 1 | BV13: 保时捷 | BY13: 1 | BZ13: 6
A14: 12 | B14: Nissan Leaf Nismo RC | C14: RC | D14: Nissan | E14: rc | F14: D | G14: ★★★★ | H14: 2.2 | I14: 1569 | J14: 2101 | K14: 250.6 | L14: 78.87 | M14: 59.91 | N14: 65.03 | O14: 11.4 | P14: 特殊 | Q14: 30 | R14: 12 | S14: 18 | T14: 28 | W14: 88 | X14: 6000 | Y14: 6500 | Z14: 7000 | AA14: 8000 | AB14: 9000 | AC14: 14000 | AD14: 19000 | AE14: 29000 | AF14: 36500 | AG14: 46000 | AH14: 47000 | AL14: 912000 | AM14: 9000 | AN14: 7 | AO14: 18000 | AP14: 2 | AQ14: 54000 | AR14: 1 | AU14: 612000 | AV14: 1524000 | AW14: 261 | AX14: 284 | AY14: 361 | AZ14: 1 | BA14: 寻车 | BD14: 1 | BG14: 1 | BV14: 日产 尼桑 聆风
A15: 13 | B15: BMW i8 Roadster | C15: i8 | D15: BMW | E15: i8 | F15: D | G15: ★★★★ | H15: 2.7 | I15: 2247 | J15: 2122 | K15: 273.1 | L15: 79.73 | M15: 78.63 | N15: 66.87 | P15: 特殊 | Q15: 20 | R15: 30 | S15: 41 | T15: 45 | W15: 136 | X15: 15000 | Y15: 19000 | Z15: 25000 | AA15: 33000 | AB15: 47000 | AC15: 63000 | AD15: 89000 | AE15: 108000 | AF15: 120000 | AG15: 130000 | AH15: 136000 | AM15: 9000 | AN15: 7 | AO15: 18000 | AP15: 2 | AQ15: 54000 | AR15: 1 | AU15: 612000 | AW15: 285 | AX15: 294 | AY15: 375 | BA15: 联会赛事 | BN15: 1 | BS15: 可开合 | BV15: 宝马 | BX15: 1
A16: 14 | B16: Italdesign Davinci | C16: 达芬奇 | D16: Italdesign | E16: davinci | F16: D | G16: ★★★★ | H16: 2.9 | I16: 2217 | J16: 2210 | K16: 278 | L16: 83.52 | M16: 73.57 | N16: 55.34 | P16: 稀有 | Q16: 20 | R16: 30 | S16: 41 | T16: 45 | W16: 136 | X16: 7500 | Y16: 10000 | Z16: 14000 | AA16: 18000 | AB16: 26000 | AC16: 35000 | AD16: 50000 | AE16: 61000 | AF16: 68000 | AG16: 73000 | AH16: 77000 | AL16: 1758000 | AM16: 10000 | AN16: 7 | AO16: 20000 | AP16: 2 | AQ16: 60000 | AR16: 1 | AU16: 680000 | AV16: 2438000 | AW16: 290 | AY16: 372 | BA16: 联会赛事 | BE16: 1 | BN16: 1 | BU16: 1 | BV16: 达芬奇 id
A17: 15 | B17: Renault Dezir | C17: Dezir | D17: Renault | E17: dezir | F17: D | G17: ★★★★ | H17: 3.6 | I17: 2213 | J17: 2213 | K17: 293.2 | L17: 65.56 | M17: 69.43 | N17: 68.44 | P17: 稀有 | Q17: 25 | R17: 32 | S17: 40 | T17: 48 | W17: 145 | X17: 7500 | Y17: 10000 | Z17: 14000 | AA17: 18000 | AB17: 26000 | AC17: 35000 | AD17: 50000 | AE17: 61000 | AF17: 68000 | AG17: 73000 | AH17: 77000 | AL17: 1758000 | AM17: 10000 | AN17: 7 | AO17: 20000 | AP17: 2 | AQ17: 60000 | AR17: 1 | AU17: 680000 | AV17: 2438000 | AW17: 306 | AY17: 391 | BA17: 联会赛事 | BN17: 1 | BV17: 雷诺 | BX17: 1
A18: 16 | B18: Peugeot SR1 | C18: SR1 | D18: Peugeot | E18: sr1 | F18: D | G18: ★★★★ | H18: 3.8 | I18: 2307 | J18: 2307 | K18: 310.5 | L18: 71.51 | M18: 52.39 | N18: 31.19 | P18: 稀有 | Q18: 25 | R18: 32 | S18: 40 | T18: 48 | W18: 145 | X18: 7500 | Y18: 10000 | Z18: 14000 | AA18: 18000 | AB18: 26000 | AC18: 35000 | AD18: 50000 | AE18: 61000 | AF18: 68000 | AG18: 73000 | AH18: 77000 | AL18: 1758000 | AM18: 20000 | AN18: 7 | AO18: 40000 | AP18: 2 | AQ18: 120000 | AR18: 1 | AU18: 1360000 | AV18: 3118000 | AW18: 323 | AY18: 412 | BA18: 周末爆冲 | BG18: 1 | BV18: 标致
A19: 17 | B19: Infiniti Project Black S | C19: 英菲尼迪 | D19: Infiniti | E19: infiniti | F19: D | G19: ★★★★ | H19: 2.8 | I19: 2368 | J19: 2371 | K19: 281.5 | L19: 76.19 | M19: 66.98 | N19: 64.67 | P19: 稀有 | Q19: 30 | R19: 23 | S19: 33 | T19: 42 | W19: 128 | X19: 10000 | Y19: 15000 | Z19: 20000 | AA19: 25000 | AB19: 36000 | AC19: 48000 | AD19: 68000 | AE19: 82000 | AF19: 90000 | AG19: 99000 | AH19: 102000 | AL19: 2380000 | AM19: 10000 | AN19: 7 | AO19: 20000 | AP19: 2 | AQ19: 60000 | AR19: 1 | AU19: 680000 | AV19: 3060000 | AW19: 293 | AY19: 377 | BA19: 寻车 | BG19: 1 | BV19: 英菲尼迪 | BX19: 1 | BY19: 1 | BZ19: 5
A20: 18 | B20: Lotus Emeya | C20: Emeya | D20: Lotus | E20: emeya | F20: D | G20: ★★★★ | H20: 5.6 | J20: 2402 | K20: 276.5 | L20: 81.79 | M20: 75.33 | N20: 67.23 | P20: 稀有 | Q20: 30 | R20: 23 | S20: 33 | T20: 42 | W20: 128 | X20: 15000 | Y20: 19000 | Z20: 25000 | AA20: 33000 | AB20: 47000 | AC20: 63000 | AD20: 89000 | AE20: 108000 | AF20: 120000 | AG20: 130000 | AH20: 136000 | AL20: 3140000 | AM20: 16000 | AN20: 7 | AO20: 32000 | AP20: 2 | AQ20: 96000 | AR20: 1 | AU20: 1088000 | AV20: 4228000 | BA20: 通行证 | BV20: 繁花 路特斯 莲花
A21: 19 | B21: Porsche 911 Carrera RS 3.8 | C21: Carrera RS | D21: Porsche | E21: carrerars | F21: D | G21: ★★★★ | H21: 4.8 | J21: 2435 | K21: 301.9 | L21: 72.15 | M21: 71.66 | N21: 35.99 | P21: 稀有 | Q21: 30 | R21: 32 | S21: 40 | T21: 50 | X21: 15000 | Y21: 19000 | Z21: 25000 | AA21: 33000 | AB21: 47000 | AC21: 63000 | AD21: 89000 | AE21: 108000 | AF21: 120000 | AM21: 18000 | AN21: 7 | AO21: 36000 | AP21: 2 | AQ21: 108000 | AR21: 1 | AU21: 1224000 | AW21: 315 | AY21: 402 | BA21: 周末爆冲
A22: 20 | B22: Hyundai Ioniq 5 N | C22: 5N | D22: Hyundai | E22: ioniq | F22: D | G22: ★★★★ | H22: 5.5 | J22: 2559 | K22: 275.9 | L22: 88.63 | M22: 80.51 | N22: 63.38 | P22: 史诗 | Q22: 20 | R22: 30 | S22: 41 | T22: 45 | W22: 136 | BA22: 联会赛事 | BV22: 现代
A23: 21 | B23: Lotus Emira | C23: Emira | D23: Lotus | E23: emira | F23: D | G23: ★★★★ | H23: 3.4 | I23: 2611 | J23: 2612 | K23: 307.4 | L23: 70.86 | M23: 57.47 | N23: 53.42 | P23: 稀有 | Q23: 25 | R23: 32 | S23: 40 | T23: 48 | W23: 145 | X23: 10000 | Y23: 15000 | Z23: 20000 | AA23: 25000 | AB23: 36000 | AC23: 48000 | AD23: 68000 | AE23: 82000 | AF23: 90000 | AG23: 99000 | AH23: 102000 | AL23: 2380000 | AM23: 20000 | AN23: 7 | AO23: 40000 | AP23: 2 | AQ23: 120000 | AR23: 1 | AU23: 1360000 | AV23: 3740000 | AW23: 320 | AY23: 409 | BA23: 周末爆冲 | BG23: 1 | BQ23: 1款 | BV23: 路特斯 | BY23: 1 | BZ23: 5
A24: 22 | B24: Lamborghini Countach 25th Anniversary | C24: 康塔什 | D24: Lamborghini | E24: countach | F24: D | G24: ★★★★ | H24: 3.7 | I24: 2498 | J24: 2618 | K24: 305.4 | L24: 71.43 | M24: 65.58 | N24: 48.39 | P24: 稀有 | Q24: 25 | R24: 32 | S24: 40 | T24: 48 | W24: 145 | X24: 10000 | Y24: 15000 | Z24: 20000 | AA24: 25000 | AB24: 36000 | AC24: 48000 | AD24: 68000 | AE24: 82500 | AF24: 90000 | AG24: 99000 | AH24: 102000 | AL24: 2382000 | AM24: 20000 | AN24: 7 | AO24: 40000 | AP24: 2 | AQ24: 120000 | AR24: 1 | AU24: 1360000 | AV24: 3742000 | AW24: 318 | AY24: 406 | BA24: 周末爆冲 | BG24: 1 | BV24: 兰博基尼 | BY24: 1 | BZ24: 6
A25: 23 | B25: Praga R1 | C25: Praga | D25: Praga | E25: praga | F25: D | G25: ★★★★ | H25: 3.9 | I25: 2624 | J25: 2624 | K25: 283.3 | L25: 87.8 | M25: 62.25 | N25: 60.92 | P25: 稀有 | Q25: 25 | R25: 32 | S25: 40 | T25: 48 | X25: 15750 | Y25: 19700 | Z25: 25600 | AA25: 33400 | AB25: 47200 | AC25: 63000 | AD25: 88500 | AE25: 108000 | AF25: 120000 | AG25: 130000 | AH25: 136000 | AL25: 3148600 | AM25: 22500 | AN25: 7 | AO25: 45000 | AP25: 2 | AQ25: 135000 | AR25: 1 | AU25: 1530000 | AV25: 4678600 | AW25: 295 | AY25: 379 | BA25: 联会赛事 | BN25: 1
A26: 24 | B26: Ginetta G60 | C26: G60 | D26: Ginetta | E26: g60 | F26: D | G26: ★★★★ | H26: 1.8 | I26: 2646 | J26: 2632 | K26: 290.7 | L26: 71.51 | M26: 74.81 | N26: 62.66 | O26: 7.85 | P26: 特殊 | Q26: 30 | R26: 32 | S26: 40 | T26: 50 | W26: 152 | X26: 12050 | Y26: 15000 | Z26: 19500 | AA26: 25600 | AF26: 169000 | AG26: 188000 | AM26: 12500 | AN26: 7 | AO26: 25000 | AP26: 2 | AQ26: 75000 | AR26: 1 | AU26: 850000 | AW26: 303 | AY26: 388 | BA26: 寻车 | BG26: 1 | BQ26: 1款
A27: 25 | B27: Glickenhaus 004C🔑 | C27: 004C | D27: Glickenhaus | E27: 004c | F27: D | G27: ★★★★★ | H27: 3.8 | I27: 3075 | J27: 2840 | K27: 311.2 | L27: 76.75 | M27: 56.89 | N27: 60.87 | P27: 史诗 | Q27: 🔑 | R27: 30 | S27: 35 | T27: 42 | U27: 50 | W27: 157 | X27: 15000 | Y27: 20000 | Z27: 31000 | AA27: 40000 | AB27: 56000 | AC27: 75000 | AD27: 106000 | AE27: 144000 | AF27: 169000 | AG27: 188000 | AH27: 194000 | AI27: 200000 | AL27: 4952000 | AM27: 22500 | AN27: 8 | AO27: 45000 | AP27: 5 | AQ27: 135000 | AR27: 3 | AU27: 3240000 | AV27: 8192000 | AW27: 324 | AY27: 413 | BA27: 大奖赛 | BM27: 1 | BO27: 1 | BY27: 1 | BZ27: 6
A28: 26 | B28: Alfa Romeo Giulia GTAm🔑 | C28: Giulia | D28: Alfa Romeo | E28: giulia | F28: D | G28: ★★★★★ | H28: 4.5 | J28: 2895 | K28: 312.2 | L28: 77.28 | M28: 45.17 | N28: 47.09 | P28: 史诗 | Q28: 🔑 | R28: 30 | S28: 35 | T28: 42 | U28: 50 | X28: 15000 | Y28: 20000 | Z28: 31000 | AA28: 40000 | AB28: 56000 | AC28: 75000 | AD28: 106000 | AE28: 144000 | AF28: 169000 | AG28: 188000 | AH28: 194000 | AI28: 200000 | AL28: 4952000 | AM28: 24000 | AN28: 8 | AO28: 48000 | AP28: 5 | AQ28: 144000 | AR28: 3 | AU28: 3456000 | AV28: 8408000 | BA28: 大奖赛 | BM28: 1 | BO28: 1 | BV28: 阿尔法罗密欧
A29: 27 | B29: Toyota GR Supra Racing Concept | C29: Supra | D29: Toyota | E29: supraracing | F29: D | G29: ★★★★★ | H29: 5.4 | J29: 2930 | K29: 312 | L29: 71.98 | M29: 61.16 | N29: 53.66 | P29: 史诗 | Q29: 30 | R29: 12 | S29: 18 | T29: 27 | U29: 38 | W29: 125 | X29: 15000 | Y29: 20000 | Z29: 31000 | AA29: 40000 | AB29: 56000 | AC29: 75000 | AD29: 106000 | AE29: 144000 | AF29: 169000 | AG29: 188000 | AH29: 194000 | AI29: 200000 | AL29: 4952000 | AM29: 24000 | AN29: 8 | AO29: 48000 | AP29: 5 | AQ29: 144000 | AR29: 3 | AU29: 3456000 | AV29: 8408000 | BA29: 通行证
A30: 28 | B30: Ford Mustang Mach-E1400🔑 | C30: 电马 | D30: Ford | E30: e1400 | F30: D | G30: ★★★★★ | H30: 4.4 | J30: 3097 | K30: 301.2 | L30: 82.87 | M30: 51.83 | N30: 64.82 | P30: 史诗 | Q30: 🔑 | R30: 30 | S30: 35 | T30: 42 | U30: 50 | X30: 15000 | Y30: 20000 | Z30: 31000 | AA30: 40000 | AB30: 56000 | AC30: 75000 | AD30: 106000 | AE30: 144000 | AF30: 169000 | AG30: 188000 | AH30: 194000 | AI30: 200000 | AL30: 4952000 | AM30: 22750 | AN30: 8 | AO30: 45500 | AP30: 5 | AQ30: 136500 | AR30: 3 | AU30: 3276000 | AV30: 8228000 | AW30: 314 | BA30: 大奖赛 | BM30: 1 | BO30: 1 | BV30: 福特 野马
A31: 29 | B31: Kimera EVO37🔑 | C31: EVO37 | D31: Kimera | E31: evo37 | F31: D | G31: ★★★★★ | H31: 5.2 | J31: 3108 | K31: 297.8 | L31: 80.98 | M31: 78.18 | N31: 57.43 | P31: 史诗 | Q31: 🔑 | R31: 30 | S31: 35 | T31: 42 | U31: 50 | X31: 15000 | Y31: 20000 | Z31: 31000 | AA31: 40000 | AB31: 56000 | AC31: 75000 | AD31: 106000 | AE31: 144000 | AF31: 169000 | AG31: 188000 | AH31: 194000 | AI31: 200000 | AL31: 4952000 | AM31: 28000 | AN31: 8 | AO31: 56000 | AP31: 5 | AQ31: 168000 | AR31: 3 | AU31: 4032000 | AV31: 8984000 | BA31: 大奖赛 | BO31: 1
A32: 30 | B32: Lotus Evora Sport 410 | C32: 大莲花 | D32: Lotus | E32: 410 | F32: C | G32: ★★★ | H32: 1.3 | I32: 2123 | J32: 2123 | K32: 317.7 | L32: 71.7 | M32: 50.92 | N32: 47.05 | O32: 5.133 | P32: 特殊 | Q32: 20 | R32: 30 | S32: 50 | W32: 100 | X32: 6000 | Y32: 8000 | Z32: 9000 | AA32: 10000 | AB32: 12000 | AC32: 18000 | AD32: 25000 | AE32: 37000 | AF32: 46000 | AG32: 58000 | AL32: 916000 | AM32: 9000 | AN32: 4 | AO32: 18000 | AP32: 1 | AQ32: 54000 | AR32: 1 | AU32: 432000 | AV32: 1348000 | AW32: 331 | AY32: 422 | AZ32: 1 | BA32: 级别杯 | BB32: 1 | BD32: 1 | BE32: 1 | BU32: 1 | BV32: 路特斯 大莲花 | BY32: 1 | BZ32: 5
A33: 31 | B33: Dodge Challenger 392 Hemi Scat Pack | C33: 392 | D33: Dodge | E33: 392 | F33: C | G33: ★★★ | H33: 1.3 | I33: 2144 | J33: 2152 | K33: 302.7 | L33: 73.64 | M33: 43.57 | N33: 62.82 | O33: 7.48 | P33: 特殊 | Q33: 20 | R33: 30 | S33: 50 | W33: 100 | X33: 6000 | Y33: 8000 | Z33: 9000 | AA33: 10000 | AB33: 12000 | AC33: 18000 | AD33: 25000 | AE33: 37000 | AF33: 46000 | AG33: 58000 | AL33: 916000 | AM33: 9000 | AN33: 4 | AO33: 18000 | AP33: 1 | AQ33: 54000 | AR33: 1 | AU33: 432000 | AV33: 1348000 | AW33: 315 | AY33: 403 | AZ33: 1 | BA33: 级别杯 | BD33: 1 | BE33: 1 | BU33: 1 | BV33: 道奇 挑战者 | BY33: 1 | BZ33: 5
A34: 32 | B34: Porsche 911 GTS Coupe | C34: 911GTS | D34: Porsche | E34: 911 | F34: C | G34: ★★★ | H34: 1.3 | I34: 2186 | J34: 2185 | K34: 328.7 | L34: 71.21 | M34: 45.84 | N34: 56.6 | O34: 5.983 | P34: 特殊 | Q34: 25 | R34: 30 | S34: 50 | W34: 105 | X34: 6000 | Y34: 8000 | Z34: 9000 | AA34: 10000 | AB34: 12000 | AC34: 18000 | AD34: 25000 | AE34: 37000 | AF34: 46000 | AG34: 58000 | AL34: 916000 | AM34: 9000 | AN34: 4 | AO34: 18000 | AP34: 1 | AQ34: 54000 | AR34: 1 | AU34: 432000 | AV34: 1348000 | AW34: 342 | AY34: 441 | AZ34: 1 | BA34: 级别杯 | BD34: 1 | BE34: 1 | BR34: 1 | BU34: 1 | BV34: 保时捷 | BY34: 1 | BZ34: 5
A35: 33 | B35: Mercedes-Benz AMG GT S | C35: AMG | D35: Mercedes-Benz | E35: amg | F35: C | G35: ★★★ | H35: 1.3 | I35: 2281 | J35: 2281 | K35: 329.4 | L35: 71.34 | M35: 42.69 | N35: 54.66 | O35: 5.749 | P35: 特殊 | Q35: 25 | R35: 30 | S35: 50 | W35: 105 | X35: 6000 | Y35: 8000 | Z35: 10000 | AA35: 12000 | AB35: 15000 | AC35: 22000 | AD35: 31000 | AE35: 48000 | AF35: 60000 | AG35: 75000 | AL35: 1148000 | AM35: 10000 | AN35: 4 | AO35: 20000 | AP35: 1 | AQ35: 60000 | AR35: 1 | AU35: 480000 | AV35: 1628000 | AW35: 343 | AY35: 442 | AZ35: 1 | BA35: 级别杯 | BD35: 1 | BE35: 1 | BR35: 1 | BU35: 1 | BV35: 奔驰 | BY35: 1 | BZ35: 5
A36: 34 | B36: Aston Martin DB11 | C36: DB11 | D36: Aston Martin | E36: db11 | F36: C | G36: ★★★ | H36: 1.3 | I36: 2330 | J36: 2330 | K36: 340.4 | L36: 74.2 | M36: 43.21 | N36: 55.4 | O36: 5.666 | P36: 特殊 | Q36: 25 | R36: 30 | S36: 50 | W36: 105 | X36: 6000 | Y36: 8000 | Z36: 10000 | AA36: 12000 | AB36: 15000 | AC36: 22000 | AD36: 31000 | AE36: 48000 | AF36: 60000 | AG36: 75000 | AL36: 1148000 | AM36: 10000 | AN36: 4 | AO36: 20000 | AP36: 1 | AQ36: 60000 | AR36: 1 | AU36: 480000 | AV36: 1628000 | AW36: 354 | AY36: 462 | AZ36: 1 | BA36: 级别杯 | BE36: 1 | BG36: 1 | BU36: 1 | BV36: 阿斯顿马丁 | BY36: 1 | BZ36: 5
A37: 35 | B37: Porsche 718 Cayman | C37: 718 | D37: Porsche | E37: 718 | F37: C | G37: ★★★★ | H37: 1.3 | I37: 2360 | J37: 2344 | K37: 295.6 | L37: 70.52 | M37: 61.9 | N37: 60.28 | O37: 7.17 | P37: 特殊 | Q37: 25 | R37: 18 | S37: 21 | T37: 32 | W37: 96 | X37: 6000 | Y37: 8000 | Z37: 9000 | AA37: 10000 | AB37: 12000 | AC37: 18000 | AD37: 25000 | AE37: 37000 | AF37: 46000 | AG37: 48000 | AH37: 50000 | AL37: 1076000 | AM37: 10000 | AN37: 6 | AO37: 20000 | AP37: 3 | AQ37: 60000 | AR37: 1 | AU37: 720000 | AV37: 1796000 | AW37: 308 | AY37: 394 | AZ37: 1 | BA37: 级别杯 | BD37: 1 | BE37: 1 | BG37: 1 | BR37: 1 | BU37: 1 | BV37: 保时捷
A38: 36 | B38: Lotus Elise Sprint 220 | C38: 小莲花 | D38: Lotus | E38: 220 | F38: C | G38: ★★★★ | H38: 1.3 | I38: 2390 | J38: 2363 | K38: 269.5 | L38: 82.25 | M38: 83.47 | N38: 72.71 | O38: 13.382 | P38: 特殊 | Q38: 25 | R38: 18 | S38: 21 | T38: 32 | W38: 96 | X38: 7400 | Y38: 8100 | Z38: 9600 | AA38: 11900 | AB38: 17800 | AC38: 23500 | AD38: 33500 | AE38: 40500 | AF38: 44500 | AG38: 49000 | AH38: 50000 | AL38: 1183200 | AM38: 10000 | AN38: 6 | AO38: 20000 | AP38: 3 | AQ38: 60000 | AR38: 1 | AU38: 720000 | AV38: 1903200 | AW38: 282 | AY38: 363 | AZ38: 5 | BA38: 寻车 | BD38: 1 | BG38: 1 | BQ38: 1款 | BV38: 路特斯 小莲花
A39: 37 | B39: BMW M4 GTS | C39: m4 | D39: BMW | E39: m4 | F39: C | G39: ★★★ | H39: 1.3 | I39: 2447 | J39: 2447 | K39: 326.5 | L39: 73.72 | M39: 51.19 | N39: 52.48 | O39: 5.549 | P39: 特殊 | Q39: 25 | R39: 30 | S39: 50 | W39: 105 | X39: 13150 | Y39: 14100 | Z39: 15000 | AA39: 16900 | AB39: 18800 | AC39: 28000 | AD39: 39500 | AE39: 60000 | AF39: 75000 | AG39: 95000 | AL39: 1501800 | AM39: 10000 | AN39: 4 | AO39: 20000 | AP39: 1 | AQ39: 60000 | AR39: 1 | AU39: 480000 | AV39: 1981800 | AW39: 340 | AY39: 437 | AZ39: 1 | BA39: 级别杯 | BD39: 1 | BE39: 1 | BG39: 1 | BU39: 1 | BV39: 宝马
A40: 38 | B40: Jaguar F-Type SVR | C40: 捷豹 | D40: Jaguar | E40: svr | F40: C | G40: ★★★★ | H40: 1.3 | I40: 2500 | J40: 2487 | K40: 340.3 | L40: 75.55 | M40: 49.28 | N40: 50.12 | O40: 5.166 | P40: 特殊 | Q40: 30 | R40: 18 | S40: 21 | T40: 32 | W40: 101 | X40: 9400 | Y40: 10300 | Z40: 12200 | AA40: 15000 | AB40: 22500 | AC40: 30000 | AD40: 42000 | AE40: 51500 | AF40: 56500 | AG40: 62000 | AH40: 64000 | AM40: 10000 | AN40: 6 | AO40: 20000 | AP40: 3 | AQ40: 60000 | AR40: 1 | AU40: 720000 | AW40: 354 | AY40: 461 | BA40: 级别杯 | BE40: 1 | BG40: 1 | BQ40: 1款 | BU40: 1 | BV40: 捷豹 | BX40: 1 | BY40: 1 | BZ40: 5
...

Sheet 统计数据
A1: 版本 | B1: 2.0.0
A2: 蓝色零件 | B2: =SUM(全车数据表!AM3:AM96)*4 -> 6787000
A3: 紫色零件 | B3: =SUM(全车数据表!AO3:AO96)*4 -> 13574000
A4: MAX金币 | B4: =SUM(全车数据表!AU3:AU96) -> 158954000 | D4: 相当于开服以来每天赚 | E4: =B4/DATEDIF(DATE(2019,8,8),TODAY(),"d") -> 65278.85
B7: =A7 -> 0

Sheet 数据卡片
A1: _id | B1: fullName | C1: car_id | D1: brand | E1: releaseVersion | F1: nickName | G1: carClass | H1: star | I1: quality | J1: star_1 | K1: star_2 | L1: star_3 | M1: star_4 | N1: star_5 | O1: star_6 | P1: rank | Q1: topSpeed | R1: acceleration | S1: handling | T1: nitro | U1: nitroDuration | V1: stageCost | W1: uncommonPartCost | X1: partCost | Y1: totalCost | Z1: uncommonPart | AA1: rarePart | AB1: epicPart | AC1: nitroSpeed | AD1: blueSpeed | AE1: airSpeed | AF1: getMethod | AG1: getLoot | AH1: getGoals | AI1: getClassCup | AJ1: getStore | AK1: getExclusive | AL1: getHunt | AM1: getLegendPass | AN1: getUnleash | AO1: getClassicMP | AP1: get1vs1 | AQ1: getSpecialEvent | AR1: getGrandPrix | AS1: getDriveSyndicate | AT1: keyCar | AU1: decals | AV1: decalsExclusive | AW1: bodyParts | AX1: openCar | AY1: nitroVisuals | AZ1: storeEpicPart | BA1: keyWords | BB1: packLevel
A2: =全车数据表!A3 -> 1 | B2: =全车数据表!B3 -> Mitsubishi Lancer Evolution | C2: =全车数据表!E3 -> lancer | D2: =IF(全车数据表!D3="","",全车数据表!D3) -> Mitsubishi | E2: =全车数据表!H3 -> 1.3 | F2: =全车数据表!C3 -> 三菱 | G2: =全车数据表!F3 -> D | H2: =LEN(全车数据表!G3) -> 3 | I2: =VLOOKUP(全车数据表!P3,辅助计算!A:B,2,FALSE) -> uncm | J2: =全车数据表!Q3 -> 5 | K2: =全车数据表!R3 -> 8 | L2: =全车数据表!S3 -> 30 | M2: =全车数据表!T3 -> 0 | N2: =全车数据表!U3 -> 0 | O2: =全车数据表!V3 -> 0 | P2: =全车数据表!J3 -> 1381 | Q2: =全车数据表!K3 -> 270.1 | R2: =全车数据表!L3 -> 55.03 | S2: =全车数据表!M3 -> 53.79 | T2: =全车数据表!N3 -> 68.19 | U2: =全车数据表!O3 -> 10.75 | V2: =全车数据表!AL3 -> 559000 | W2: =全车数据表!AM3 -> 5000 | X2: =全车数据表!AU3 -> 140000 | Y2: =全车数据表!AV3 -> 699000 | Z2: =全车数据表!AN3 -> 5 | AA2: =全车数据表!AP3 -> 1 | AB2: =全车数据表!AR3 -> 0 | AC2: =全车数据表!AW3 -> 282 | AD2: =全车数据表!AX3 -> 0 | AE2: =全车数据表!AY3 -> 363 | AF2: =IF(全车数据表!BA3="","",全车数据表!BA3) -> 级别杯 | AG2: =IF(全车数据表!BB3="","",全车数据表!BB3) | AH2: =IF(全车数据表!BC3="","",全车数据表!BC3) | AI2: =IF(全车数据表!BD3="","",全车数据表!BD3) -> 1 | AJ2: =IF(全车数据表!BE3="","",全车数据表!BE3) -> 1 | AK2: =IF(全车数据表!BF3="","",全车数据表!BF3) | AL2: =IF(全车数据表!BG3="","",全车数据表!BG3) | AM2: =IF(全车数据表!BH3="","",全车数据表!BH3) | ... BA2: =IF(全车数据表!BV3="","",全车数据表!BV3) -> 天赐三菱 | BB2: =IF(全车数据表!AZ3="","",全车数据表!AZ3) -> 1
A3: =全车数据表!A4 -> 2 | B3: =全车数据表!B4 -> BMW Z4 LCI E89 | C3: =全车数据表!E4 -> z4 | D3: =IF(全车数据表!D4="","",全车数据表!D4) -> BMW | E3: =全车数据表!H4 -> 1.3 | F3: =全车数据表!C4 -> Z4 | G3: =全车数据表!F4 -> D | H3: =LEN(全车数据表!G4) -> 3 | I3: =VLOOKUP(全车数据表!P4,辅助计算!A:B,2,FALSE) -> uncm | J3: =全车数据表!Q4 -> 5 | K3: =全车数据表!R4 -> 8 | L3: =全车数据表!S4 -> 45 | M3: =全车数据表!T4 -> 0 | N3: =全车数据表!U4 -> 0 | O3: =全车数据表!V4 -> 0 | P3: =全车数据表!J4 -> 1476 | Q3: =全车数据表!K4 -> 266.8 | R3: =全车数据表!L4 -> 68.86 | S3: =全车数据表!M4 -> 47.43 | T3: =全车数据表!N4 -> 57.49 | U3: =全车数据表!O4 -> 7.466 | V3: =全车数据表!AL4 -> 555000 | W3: =全车数据表!AM4 -> 5000 | X3: =全车数据表!AU4 -> 140000 | Y3: =全车数据表!AV4 -> 695000 | Z3: =全车数据表!AN4 -> 5 | AA3: =全车数据表!AP4 -> 1 | AB3: =全车数据表!AR4 -> 0 | AC3: =全车数据表!AW4 -> 278 | AD3: =全车数据表!AX4 -> 0 | AE3: =全车数据表!AY4 -> 359 | AF3: =IF(全车数据表!BA4="","",全车数据表!BA4) -> 级别杯 | AG3: =IF(全车数据表!BB4="","",全车数据表!BB4) | AH3: =IF(全车数据表!BC4="","",全车数据表!BC4) | AI3: =IF(全车数据表!BD4="","",全车数据表!BD4) -> 1 | AJ3: =IF(全车数据表!BE4="","",全车数据表!BE4) -> 1 | AK3: =IF(全车数据表!BF4="","",全车数据表!BF4) | AL3: =IF(全车数据表!BG4="","",全车数据表!BG4) | AM3: =IF(全车数据表!BH4="","",全车数据表!BH4) | ... BA3: =IF(全车数据表!BV4="","",全车数据表!BV4) -> 宝马 | BB3: =IF(全车数据表!AZ4="","",全车数据表!AZ4) -> 1
A4: =全车数据表!A5 -> 3 | B4: =全车数据表!B5 -> Chevrolet Camaro LT | C4: =全车数据表!E5 -> lt | D4: =IF(全车数据表!D5="","",全车数据表!D5) -> Chevrolet | E4: =全车数据表!H5 -> 1.3 | F4: =全车数据表!C5 -> LT | G4: =全车数据表!F5 -> D | H4: =LEN(全车数据表!G5) -> 3 | I4: =VLOOKUP(全车数据表!P5,辅助计算!A:B,2,FALSE) -> uncm | J4: =全车数据表!Q5 -> 5 | K4: =全车数据表!R5 -> 12 | L4: =全车数据表!S5 -> 30 | M4: =全车数据表!T5 -> 0 | N4: =全车数据表!U5 -> 0 | O4: =全车数据表!V5 -> 0 | P4: =全车数据表!J5 -> 1546 | Q4: =全车数据表!K5 -> 284.1 | R4: =全车数据表!L5 -> 64.81 | S4: =全车数据表!M5 -> 48.39 | T4: =全车数据表!N5 -> 63.29 | U4: =全车数据表!O5 -> 8.249 | V4: =全车数据表!AL5 -> 555000 | W4: =全车数据表!AM5 -> 5000 | X4: =全车数据表!AU5 -> 140000 | Y4: =全车数据表!AV5 -> 695000 | Z4: =全车数据表!AN5 -> 5 | AA4: =全车数据表!AP5 -> 1 | AB4: =全车数据表!AR5 -> 0 | AC4: =全车数据表!AW5 -> 296 | AD4: =全车数据表!AX5 -> 0 | AE4: =全车数据表!AY5 -> 380 | AF4: =IF(全车数据表!BA5="","",全车数据表!BA5) -> 级别杯 | AG4: =IF(全车数据表!BB5="","",全车数据表!BB5) -> 1 | AH4: =IF(全车数据表!BC5="","",全车数据表!BC5) | AI4: =IF(全车数据表!BD5="","",全车数据表!BD5) -> 1 | AJ4: =IF(全车数据表!BE5="","",全车数据表!BE5) -> 1 | AK4: =IF(全车数据表!BF5="","",全车数据表!BF5) | AL4: =IF(全车数据表!BG5="","",全车数据表!BG5) | AM4: =IF(全车数据表!BH5="","",全车数据表!BH5) | ... BA4: =IF(全车数据表!BV5="","",全车数据表!BV5) -> 雪佛兰科迈罗 | BB4: =IF(全车数据表!AZ5="","",全车数据表!AZ5) -> 1
A5: =全车数据表!A6 -> 4 | B5: =全车数据表!B6 -> Nissan 370Z Nismo | C5: =全车数据表!E6 -> 370 | D5: =IF(全车数据表!D6="","",全车数据表!D6) -> Nissan | E5: =全车数据表!H6 -> 1.3 | F5: =全车数据表!C6 -> 370 | G5: =全车数据表!F6 -> D | H5: =LEN(全车数据表!G6) -> 3 | I5: =VLOOKUP(全车数据表!P6,辅助计算!A:B,2,FALSE) -> uncm | J5: =全车数据表!Q6 -> 10 | K5: =全车数据表!R6 -> 12 | L5: =全车数据表!S6 -> 30 | M5: =全车数据表!T6 -> 0 | N5: =全车数据表!U6 -> 0 | O5: =全车数据表!V6 -> 0 | P5: =全车数据表!J6 -> 1662 | Q5: =全车数据表!K6 -> 268.5 | R5: =全车数据表!L6 -> 66.61 | S5: =全车数据表!M6 -> 81.83 | T5: =全车数据表!N6 -> 67.07 | U5: =全车数据表!O6 -> 10.35 | V5: =全车数据表!AL6 -> 554000 | W5: =全车数据表!AM6 -> 5000 | X5: =全车数据表!AU6 -> 140000 | Y5: =全车数据表!AV6 -> 694000 | Z5: =全车数据表!AN6 -> 5 | AA5: =全车数据表!AP6 -> 1 | AB5: =全车数据表!AR6 -> 0 | AC5: =全车数据表!AW6 -> 280 | AD5: =全车数据表!AX6 -> 0 | AE5: =全车数据表!AY6 -> 361 | AF5: =IF(全车数据表!BA6="","",全车数据表!BA6) -> 级别杯 | AG5: =IF(全车数据表!BB6="","",全车数据表!BB6) -> 1 | AH5: =IF(全车数据表!BC6="","",全车数据表!BC6) | AI5: =IF(全车数据表!BD6="","",全车数据表!BD6) -> 1 | AJ5: =IF(全车数据表!BE6="","",全车数据表!BE6) -> 1 | AK5: =IF(全车数据表!BF6="","",全车数据表!BF6) | AL5: =IF(全车数据表!BG6="","",全车数据表!BG6) | AM5: =IF(全车数据表!BH6="","",全车数据表!BH6) | ... BA5: =IF(全车数据表!BV6="","",全车数据表!BV6) -> 日产 尼桑 | BB5: =IF(全车数据表!AZ6="","",全车数据表!AZ6) -> 1
A6: =全车数据表!A7 -> 5 | B6: =全车数据表!B7 -> Dodge Challenger SRT8 | C6: =全车数据表!E7 -> srt8 | D6: =IF(全车数据表!D7="","",全车数据表!D7) -> Dodge | E6: =全车数据表!H7 -> 1.3 | F6: =全车数据表!C7 -> srt8 | G6: =全车数据表!F7 -> D | H6: =LEN(全车数据表!G7) -> 3 | I6: =VLOOKUP(全车数据表!P7,辅助计算!A:B,2,FALSE) -> uncm | J6: =全车数据表!Q7 -> 15 | K6: =全车数据表!R7 -> 20 | L6: =全车数据表!S7 -> 30 | M6: =全车数据表!T7 -> 0 | N6: =全车数据表!U7 -> 0 | O6: =全车数据表!V7 -> 0 | P6: =全车数据表!J7 -> 1683 | Q6: =全车数据表!K7 -> 308.4 | R6: =全车数据表!L7 -> 71.92 | S6: =全车数据表!M7 -> 37.98 | T6: =全车数据表!N7 -> 45.41 | U6: =全车数据表!O7 -> 5.05 | V6: =全车数据表!AL7 -> 554000 | W6: =全车数据表!AM7 -> 5000 | X6: =全车数据表!AU7 -> 140000 | Y6: =全车数据表!AV7 -> 694000 | Z6: =全车数据表!AN7 -> 5 | AA6: =全车数据表!AP7 -> 1 | AB6: =全车数据表!AR7 -> 0 | AC6: =全车数据表!AW7 -> 321 | AD6: =全车数据表!AX7 -> 0 | AE6: =全车数据表!AY7 -> 410 | AF6: =IF(全车数据表!BA7="","",全车数据表!BA7) -> 级别杯 | AG6: =IF(全车数据表!BB7="","",全车数据表!BB7) | AH6: =IF(全车数据表!BC7="","",全车数据表!BC7) | AI6: =IF(全车数据表!BD7="","",全车数据表!BD7) -> 1 | AJ6: =IF(全车数据表!BE7="","",全车数据表!BE7) -> 1 | AK6: =IF(全车数据表!BF7="","",全车数据表!BF7) | AL6: =IF(全车数据表!BG7="","",全车数据表!BG7) | AM6: =IF(全车数据表!BH7="","",全车数据表!BH7) | ... BA6: =IF(全车数据表!BV7="","",全车数据表!BV7) -> 道奇 挑战者 送人头 e霸 | BB6: =IF(全车数据表!AZ7="","",全车数据表!AZ7) -> 1
A7: =全车数据表!A8 -> 6 | B7: =全车数据表!B8 -> KTM X-Bow GTX | C7: =全车数据表!E8 -> gtx | D7: =IF(全车数据表!D8="","",全车数据表!D8) -> KTM | E7: =全车数据表!H8 -> 4.1 | F7: =全车数据表!C8 -> GTX | G7: =全车数据表!F8 -> D | H7: =LEN(全车数据表!G8) -> 3 | I7: =VLOOKUP(全车数据表!P8,辅助计算!A:B,2,FALSE) -> uncm | J7: =全车数据表!Q8 -> 20 | K7: =全车数据表!R8 -> 25 | L7: =全车数据表!S8 -> 30 | M7: =全车数据表!T8 -> 0 | N7: =全车数据表!U8 -> 0 | O7: =全车数据表!V8 -> 0 | P7: =全车数据表!J8 -> 1738 | Q7: =全车数据表!K8 -> 247.5 | R7: =全车数据表!L8 -> 83.84 | S7: =全车数据表!M8 -> 64.99 | T7: =全车数据表!N8 -> 66.99 | U7: =全车数据表!O8 -> 0 | V7: =全车数据表!AL8 -> 724000 | W7: =全车数据表!AM8 -> 6000 | X7: =全车数据表!AU8 -> 168000 | Y7: =全车数据表!AV8 -> 892000 | Z7: =全车数据表!AN8 -> 5 | AA7: =全车数据表!AP8 -> 1 | AB7: =全车数据表!AR8 -> 0 | AC7: =全车数据表!AW8 -> 258 | AD7: =全车数据表!AX8 -> 274 | AE7: =全车数据表!AY8 -> 350 | AF7: =IF(全车数据表!BA8="","",全车数据表!BA8) -> 周末爆冲 | AG7: =IF(全车数据表!BB8="","",全车数据表!BB8) | AH7: =IF(全车数据表!BC8="","",全车数据表!BC8) | AI7: =IF(全车数据表!BD8="","",全车数据表!BD8) | AJ7: =IF(全车数据表!BE8="","",全车数据表!BE8) | AK7: =IF(全车数据表!BF8="","",全车数据表!BF8) | AL7: =IF(全车数据表!BG8="","",全车数据表!BG8) | AM7: =IF(全车数据表!BH8="","",全车数据表!BH8) | ... BA7: =IF(全车数据表!BV8="","",全车数据表!BV8) | BB7: =IF(全车数据表!AZ8="","",全车数据表!AZ8)
A8: =全车数据表!A9 -> 7 | B8: =全车数据表!B9 -> Volkswagen XL Sport Concept | C8: =全车数据表!E9 -> xl | D8: =IF(全车数据表!D9="","",全车数据表!D9) -> Volkswagen | E8: =全车数据表!H9 -> 1.3 | F8: =全车数据表!C9 -> 大众 | G8: =全车数据表!F9 -> D | H8: =LEN(全车数据表!G9) -> 3 | I8: =VLOOKUP(全车数据表!P9,辅助计算!A:B,2,FALSE) -> uncm | J8: =全车数据表!Q9 -> 15 | K8: =全车数据表!R9 -> 20 | L8: =全车数据表!S9 -> 30 | M8: =全车数据表!T9 -> 0 | N8: =全车数据表!U9 -> 0 | O8: =全车数据表!V9 -> 0 | P8: =全车数据表!J9 -> 1814 | Q8: =全车数据表!K9 -> 291.2 | R8: =全车数据表!L9 -> 60.31 | S8: =全车数据表!M9 -> 62.02 | T8: =全车数据表!N9 -> 61.94 | U8: =全车数据表!O9 -> 7.65 | V8: =全车数据表!AL9 -> 727000 | W8: =全车数据表!AM9 -> 7500 | X8: =全车数据表!AU9 -> 210000 | Y8: =全车数据表!AV9 -> 937000 | Z8: =全车数据表!AN9 -> 5 | AA8: =全车数据表!AP9 -> 1 | AB8: =全车数据表!AR9 -> 0 | AC8: =全车数据表!AW9 -> 303 | AD8: =全车数据表!AX9 -> 0 | AE8: =全车数据表!AY9 -> 389 | AF8: =IF(全车数据表!BA9="","",全车数据表!BA9) -> 级别杯 | AG8: =IF(全车数据表!BB9="","",全车数据表!BB9) | AH8: =IF(全车数据表!BC9="","",全车数据表!BC9) | AI8: =IF(全车数据表!BD9="","",全车数据表!BD9) -> 1 | AJ8: =IF(全车数据表!BE9="","",全车数据表!BE9) -> 1 | AK8: =IF(全车数据表!BF9="","",全车数据表!BF9) | AL8: =IF(全车数据表!BG9="","",全车数据表!BG9) | AM8: =IF(全车数据表!BH9="","",全车数据表!BH9) | ... BA8: =IF(全车数据表!BV9="","",全车数据表!BV9) -> 大众 | BB8: =IF(全车数据表!AZ9="","",全车数据表!AZ9) -> 1
A9: =全车数据表!A10 -> 8 | B9: =全车数据表!B10 -> BMW 3.0 CSL Hommage | C9: =全车数据表!E10 -> hommage | D9: =IF(全车数据表!D10="","",全车数据表!D10) -> BMW | E9: =全车数据表!H10 -> 1.3 | F9: =全车数据表!C10 -> 宝马3.0 | G9: =全车数据表!F10 -> D | H9: =LEN(全车数据表!G10) -> 3 | I9: =VLOOKUP(全车数据表!P10,辅助计算!A:B,2,FALSE) -> uncm | J9: =全车数据表!Q10 -> 20 | K9: =全车数据表!R10 -> 20 | L9: =全车数据表!S10 -> 30 | M9: =全车数据表!T10 -> 0 | N9: =全车数据表!U10 -> 0 | O9: =全车数据表!V10 -> 0 | P9: =全车数据表!J10 -> 1827 | Q9: =全车数据表!K10 -> 297.5 | R9: =全车数据表!L10 -> 73.39 | S9: =全车数据表!M10 -> 50.08 | T9: =全车数据表!N10 -> 51.2 | U9: =全车数据表!O10 -> 5.782 | V9: =全车数据表!AL10 -> 727000 | W9: =全车数据表!AM10 -> 7500 | X9: =全车数据表!AU10 -> 210000 | Y9: =全车数据表!AV10 -> 937000 | Z9: =全车数据表!AN10 -> 5 | AA9: =全车数据表!AP10 -> 1 | AB9: =全车数据表!AR10 -> 0 | AC9: =全车数据表!AW10 -> 310 | AD9: =全车数据表!AX10 -> 0 | AE9: =全车数据表!AY10 -> 396 | AF9: =IF(全车数据表!BA10="","",全车数据表!BA10) -> 级别杯 | AG9: =IF(全车数据表!BB10="","",全车数据表!BB10) | AH9: =IF(全车数据表!BC10="","",全车数据表!BC10) | AI9: =IF(全车数据表!BD10="","",全车数据表!BD10) -> 1 | AJ9: =IF(全车数据表!BE10="","",全车数据表!BE10) -> 1 | AK9: =IF(全车数据表!BF10="","",全车数据表!BF10) | AL9: =IF(全车数据表!BG10="","",全车数据表!BG10) | AM9: =IF(全车数据表!BH10="","",全车数据表!BH10) | ... BA9: =IF(全车数据表!BV10="","",全车数据表!BV10) -> 宝马 | BB9: =IF(全车数据表!AZ10="","",全车数据表!AZ10) -> 1
A10: =全车数据表!A11 -> 9 | B10: =全车数据表!B11 -> Chevrolet Camaro ZL1 50TH Edition | C10: =全车数据表!E11 -> 50th | D10: =IF(全车数据表!D11="","",全车数据表!D11) -> Chevrolet | E10: =全车数据表!H11 -> 1.3 | F10: =全车数据表!C11 -> 50th | G10: =全车数据表!F11 -> D | H10: =LEN(全车数据表!G11) -> 3 | I10: =VLOOKUP(全车数据表!P11,辅助计算!A:B,2,FALSE) -> uncm | J10: =全车数据表!Q11 -> 20 | K10: =全车数据表!R11 -> 20 | L10: =全车数据表!S11 -> 30 | M10: =全车数据表!T11 -> 0 | N10: =全车数据表!U11 -> 0 | O10: =全车数据表!V11 -> 0 | P10: =全车数据表!J11 -> 1971 | Q10: =全车数据表!K11 -> 272.1 | R10: =全车数据表!L11 -> 78.14 | S10: =全车数据表!M11 -> 83.14 | T10: =全车数据表!N11 -> 72.33 | U10: =全车数据表!O11 -> 13.016 | V10: =全车数据表!AL11 -> 1082000 | W10: =全车数据表!AM11 -> 7500 | X10: =全车数据表!AU11 -> 210000 | Y10: =全车数据表!AV11 -> 1292000 | Z10: =全车数据表!AN11 -> 5 | AA10: =全车数据表!AP11 -> 1 | AB10: =全车数据表!AR11 -> 0 | AC10: =全车数据表!AW11 -> 284 | AD10: =全车数据表!AX11 -> 0 | AE10: =全车数据表!AY11 -> 365 | AF10: =IF(全车数据表!BA11="","",全车数据表!BA11) -> 传奇商店 | AG10: =IF(全车数据表!BB11="","",全车数据表!BB11) | AH10: =IF(全车数据表!BC11="","",全车数据表!BC11) | AI10: =IF(全车数据表!BD11="","",全车数据表!BD11) | AJ10: =IF(全车数据表!BE11="","",全车数据表!BE11) -> 1 | AK10: =IF(全车数据表!BF11="","",全车数据表!BF11) | AL10: =IF(全车数据表!BG11="","",全车数据表!BG11) | AM10: =IF(全车数据表!BH11="","",全车数据表!BH11) | ... BA10: =IF(全车数据表!BV11="","",全车数据表!BV11) -> 雪佛兰 科迈罗 | BB10: =IF(全车数据表!AZ11="","",全车数据表!AZ11) -> 8
A11: =全车数据表!A12 -> 10 | B11: =全车数据表!B12 -> DS Automobiles DS E-Tense | C11: =全车数据表!E12 -> ds | D11: =IF(全车数据表!D12="","",全车数据表!D12) -> DS Automobiles | E11: =全车数据表!H12 -> 1.3 | F11: =全车数据表!C12 -> DS | G11: =全车数据表!F12 -> D | H11: =LEN(全车数据表!G12) -> 3 | I11: =VLOOKUP(全车数据表!P12,辅助计算!A:B,2,FALSE) -> uncm | J11: =全车数据表!Q12 -> 20 | K11: =全车数据表!R12 -> 25 | L11: =全车数据表!S12 -> 30 | M11: =全车数据表!T12 -> 0 | N11: =全车数据表!U12 -> 0 | O11: =全车数据表!V12 -> 0 | P11: =全车数据表!J12 -> 1976 | Q11: =全车数据表!K12 -> 270.1 | R11: =全车数据表!L12 -> 76.07 | S11: =全车数据表!M12 -> 81.27 | T11: =全车数据表!N12 -> 72.3 | U11: =全车数据表!O12 -> 13.1 | V11: =全车数据表!AL12 -> 0 | W11: =全车数据表!AM12 -> 7500 | X11: =全车数据表!AU12 -> 210000 | Y11: =全车数据表!AV12 -> 0 | Z11: =全车数据表!AN12 -> 5 | AA11: =全车数据表!AP12 -> 1 | AB11: =全车数据表!AR12 -> 0 | AC11: =全车数据表!AW12 -> 282 | AD11: =全车数据表!AX12 -> 0 | AE11: =全车数据表!AY12 -> 363 | AF11: =IF(全车数据表!BA12="","",全车数据表!BA12) -> 级别杯 | AG11: =IF(全车数据表!BB12="","",全车数据表!BB12) | AH11: =IF(全车数据表!BC12="","",全车数据表!BC12) | AI11: =IF(全车数据表!BD12="","",全车数据表!BD12) | AJ11: =IF(全车数据表!BE12="","",全车数据表!BE12) | AK11: =IF(全车数据表!BF12="","",全车数据表!BF12) | AL11: =IF(全车数据表!BG12="","",全车数据表!BG12) | AM11: =IF(全车数据表!BH12="","",全车数据表!BH12) | ... BA11: =IF(全车数据表!BV12="","",全车数据表!BV12) -> 屌丝龙 | BB11: =IF(全车数据表!AZ12="","",全车数据表!AZ12) -> 8
A12: =全车数据表!A13 -> 11 | B12: =全车数据表!B13 -> Porsche Boxster 25th | C12: =全车数据表!E13 -> boxster | D12: =IF(全车数据表!D13="","",全车数据表!D13) -> Porsche | E12: =全车数据表!H13 -> 3.9 | F12: =全车数据表!C13 -> Boxster | G12: =全车数据表!F13 -> D | H12: =LEN(全车数据表!G13) -> 4 | I12: =VLOOKUP(全车数据表!P13,辅助计算!A:B,2,FALSE) -> rare | J12: =全车数据表!Q13 -> 20 | K12: =全车数据表!R13 -> 30 | L12: =全车数据表!S13 -> 41 | M12: =全车数据表!T13 -> 45 | N12: =全车数据表!U13 -> 0 | O12: =全车数据表!V13 -> 0 | P12: =全车数据表!J13 -> 1985 | Q12: =全车数据表!K13 -> 298.7 | R12: =全车数据表!L13 -> 72.12 | S12: =全车数据表!M13 -> 46.1 | T12: =全车数据表!N13 -> 54.35 | U12: =全车数据表!O13 -> 0 | V12: =全车数据表!AL13 -> 1758000 | W12: =全车数据表!AM13 -> 16500 | X12: =全车数据表!AU13 -> 1122000 | Y12: =全车数据表!AV13 -> 2880000 | Z12: =全车数据表!AN13 -> 7 | AA12: =全车数据表!AP13 -> 2 | AB12: =全车数据表!AR13 -> 1 | AC12: =全车数据表!AW13 -> 311 | AD12: =全车数据表!AX13 -> 0 | AE12: =全车数据表!AY13 -> 398 | AF12: =IF(全车数据表!BA13="","",全车数据表!BA13) -> 周末爆冲 | AG12: =IF(全车数据表!BB13="","",全车数据表!BB13) | AH12: =IF(全车数据表!BC13="","",全车数据表!BC13) | AI12: =IF(全车数据表!BD13="","",全车数据表!BD13) | AJ12: =IF(全车数据表!BE13="","",全车数据表!BE13) | AK12: =IF(全车数据表!BF13="","",全车数据表!BF13) | AL12: =IF(全车数据表!BG13="","",全车数据表!BG13) -> 1 | AM12: =IF(全车数据表!BH13="","",全车数据表!BH13) | ... BA12: =IF(全车数据表!BV13="","",全车数据表!BV13) -> 保时捷 | BB12: =IF(全车数据表!AZ13="","",全车数据表!AZ13)
A13: =全车数据表!A14 -> 12 | B13: =全车数据表!B14 -> Nissan Leaf Nismo RC | C13: =全车数据表!E14 -> rc | D13: =IF(全车数据表!D14="","",全车数据表!D14) -> Nissan | E13: =全车数据表!H14 -> 2.2 | F13: =全车数据表!C14 -> RC | G13: =全车数据表!F14 -> D | H13: =LEN(全车数据表!G14) -> 4 | I13: =VLOOKUP(全车数据表!P14,辅助计算!A:B,2,FALSE) -> uncm | J13: =全车数据表!Q14 -> 30 | K13: =全车数据表!R14 -> 12 | L13: =全车数据表!S14 -> 18 | M13: =全车数据表!T14 -> 28 | N13: =全车数据表!U14 -> 0 | O13: =全车数据表!V14 -> 0 | P13: =全车数据表!J14 -> 2101 | Q13: =全车数据表!K14 -> 250.6 | R13: =全车数据表!L14 -> 78.87 | S13: =全车数据表!M14 -> 59.91 | T13: =全车数据表!N14 -> 65.03 | U13: =全车数据表!O14 -> 11.4 | V13: =全车数据表!AL14 -> 912000 | W13: =全车数据表!AM14 -> 9000 | X13: =全车数据表!AU14 -> 612000 | Y13: =全车数据表!AV14 -> 1524000 | Z13: =全车数据表!AN14 -> 7 | AA13: =全车数据表!AP14 -> 2 | AB13: =全车数据表!AR14 -> 1 | AC13: =全车数据表!AW14 -> 261 | AD13: =全车数据表!AX14 -> 284 | AE13: =全车数据表!AY14 -> 361 | AF13: =IF(全车数据表!BA14="","",全车数据表!BA14) -> 寻车 | AG13: =IF(全车数据表!BB14="","",全车数据表!BB14) | AH13: =IF(全车数据表!BC14="","",全车数据表!BC14) | AI13: =IF(全车数据表!BD14="","",全车数据表!BD14) -> 1 | AJ13: =IF(全车数据表!BE14="","",全车数据表!BE14) | AK13: =IF(全车数据表!BF14="","",全车数据表!BF14) | AL13: =IF(全车数据表!BG14="","",全车数据表!BG14) -> 1 | AM13: =IF(全车数据表!BH14="","",全车数据表!BH14) | ... BA13: =IF(全车数据表!BV14="","",全车数据表!BV14) -> 日产 尼桑 聆风 | BB13: =IF(全车数据表!AZ14="","",全车数据表!AZ14) -> 1
... A325: =全车数据表!A326 -> 324 | B325: =全车数据表!B326 -> Koenigsegg Jesko Absolut | C325: =全车数据表!E326 -> jkab | D325: =IF(全车数据表!D326="","",全车数据表!D326) -> Koenigsegg | E325: =全车数据表!H326 -> 4.1 | F325: =全车数据表!C326 -> 杰皇 | G325: =全车数据表!F326 -> R | H325: =LEN(全车数据表!G326) -> 6 | I325: =VLOOKUP(全车数据表!P326,辅助计算!A:B,2,FALSE) -> ruby | J325: =全车数据表!Q326 -> 60 | K325: =全车数据表!R326 -> 60 | L325: =全车数据表!S326 -> 62 | M325: =全车数据表!T326 -> 62 | N325: =全车数据表!U326 -> 65 | O325: =全车数据表!V326 -> 70 | P325: =全车数据表!J326 -> 5664 | Q325: =全车数据表!K326 -> 548.1 | R325: =全车数据表!L326 -> 82.27 | S325: =全车数据表!M326 -> 50.53 | T325: =全车数据表!N326 -> 52.89 | U325: =全车数据表!O326 -> 4.3 | V325: =全车数据表!AL326 -> 50000000 | W325: =全车数据表!AM326 -> 150000 | X325: =全车数据表!AU326 -> 50000000 | Y325: =全车数据表!AV326 -> 100000000 | Z325: =全车数据表!AN326 -> 4 | AA325: =全车数据表!AP326 -> 8 | AB325: =全车数据表!AR326 -> 6 | AC325: =全车数据表!AW326 -> 559 | AD325: =全车数据表!AX326 -> 0 | AE325: =全车数据表!AY326 -> 600 | AF325: =IF(全车数据表!BA326="","",全车数据表!BA326) -> 擂台挑战 | AG325: =IF(全车数据表!BB326="","",全车数据表!BB326) | AH325: =IF(全车数据表!BC326="","",全车数据表!BC326) | AI325: =IF(全车数据表!BD326="","",全车数据表!BD326) | AJ325: =IF(全车数据表!BE326="","",全车数据表!BE326) | AK325: =IF(全车数据表!BF326="","",全车数据表!BF326) | AL325: =IF(全车数据表!BG326="","",全车数据表!BG326) | AM325: =IF(全车数据表!BH326="","",全车数据表!BH326) | ... BA325: =IF(全车数据表!BV326="","",全车数据表!BV326) -> 柯尼塞格 | BB325: =IF(全车数据表!AZ326="","",全车数据表!AZ326)

Sheet 辅助计算
A1: 特殊 | B1: uncm
A2: 稀有 | B2: rare
A3: 史诗 | B3: epic
A4: 传奇 | B4: ruby

Sheet 盘点
A1: 阵营 | B1: 说明 | C1: 车辆信息 | G1: 满改数据 | H1: 理由 | I1: 图纸获取方式 | J1: 金卡获取方式
C2: 全名 | D2: 别名 | E2: 级别 | F2: 版本 | G2: 性能分
A3: 白嫖无感车 | B3: 每一个车拎出来， 似乎都没有那么强 白嫖满星就完事咯 | C3: Mitsubishi Lancer Evolution | D3: 三菱 | E3: D | F3: 1.3 | G3: 1381 | J3: 不需要金卡
C4: BMW Z4 LCI E89 | D4: z4 | E4: D | F4: 1.3 | G4: 1476 | J4: 不需要金卡
C5: Chevrolet Camaro LT | D5: LT | E5: D | F5: 1.3 | G5: 1546 | J5: 不需要金卡
C6: Nissan 370Z Nismo | D6: 370 | E6: D | F6: 1.3 | G6: 1662 | J6: 不需要金卡
C7: Dodge Challenger SRT8 | D7: srt8 | E7: D | F7: 1.3 | G7: 1683 | J7: 不需要金卡
C8: Volkswagen XL Sport Concept | D8: 大众 | E8: D | F8: 1.3 | G8: 1814 | J8: 不需要金卡
C9: BMW 3.0 CSL hommage | D9: 宝马3.0 | E9: D | F9: 1.3 | G9: 1827 | J9: 不需要金卡
C10: Lotus Evora Sport 410 | D10: 莲花 | E10: C | F10: 1.3 | G10: 2123 | J10: 红币商店
C11: Dodge Challenger 392 Hemi Scat Pack | D11: 392 | E11: C | F11: 1.3 | G11: 2152 | J11: 红币商店
C12: Porsche 911 GTS Coupe | D12: 911GTS | E12: C | F12: 1.3 | G12: 2185 | J12: 红币商店
C13: Mercedes-Benz AMG GT S | D13: 奔驰 | E13: C | F13: 1.3 | G13: 2281 | J13: 红币商店
C14: Porsche 718 Cayman | D14: 718 | E14: C | F14: 1.3 | G14: 2344 | J14: 红币商店
C15: BMW M4 GTS | D15: m4 | E15: C | F15: 1.3 | G15: 2447 | J15: 红币商店
... C21: SCG 003S | D21: 003 | E21: A | F21: 1.3 | G21: 3534 | J21: 红币商店
A22: 常驻快乐车 | B22: 性能还不错 获取也简单 | C22: Chevrolet Camaro ZL1 50TH Edition | D22: 50th | E22: D | F22: 1.3 | G22: 1971 | H22: 快乐 | I22: 免费 | J22: 不需要金卡
C23: DS Automobiles DS E-Tense | D23: DS | E23: D | F23: 1.3 | G23: 1976 | H23: 快乐 | I23: 免费 | J23: 不需要金卡
C24: Aston Martin DB11 | D24: db11 | E24: C | F24: 1.3 | G24: 2330 | H24: 接近捷豹 | I24: 免费 | J24: 红币商店
C25: Rezvani Beast X | D25: 野兽 | E25: C | F25: 1.3 | G25: 2635 | H25: 上白金，刷周赛，工具车 | I25: 独家 | J25: 独家
C26: Exotic Rides W70 | D26: w70 | E26: B | F26: 1.3 | G26: 2633 | H26: 萌新上白金 | I26: 免费 | J26: 红币商店
C27: Lamborghini Asterion | D27: 牛A | E27: B | F27: 1.3 | G27: 2983 | H27: 每日任务，上白金好伙伴 | I27: 每日任务 | J27: 红币商店
C28: Nissan GT-R Nismo | D28: GTR | E28: B | F28: 1.4 | G28: 3144 | H28: 金币买满，加速滴神 | I28: 金币 | J28: 红币商店
C29: Cadillac Cien Concept | D29: 塞恩 | E29: B | F29: 1.3 | G29: 3155 | H29: 无情工具车 | I29: 独家 | J29: 独家
C30: Ferrari LaFerrari | D30: 拉法 | E30: A | F30: 1.3 | G30: 3445 | H30: 萌新上传奇 | I30: 免费 | J30: 红币商店
C31: Apollo N | D31: 菠萝 | E31: A | F31: 1.3 | G31: 3548 | H31: 昔日滴神 | I31: 免费 | J31: 红币商店
C32: McLaren P1™ | D32: P1 | E32: A | F32: 1.3 | G32: 3602 | H32: 俱乐部赛季固定给金卡 | I32: 俱乐部、寻车 | J32: 红币商店
C33: Icona Vulcano Titanium | D33: 火山 | E33: S | F33: 1.3 | G33: 3957 | H33: 萌新冲分 | I33: 免费 | J33: 红币商店
A34: 顶级常驻车 | B34: 肝满它！ | C34: Jaguar F-type SVR | D34: 捷豹 | E34: C | F34: 1.3 | G34: 2487 | H34: 周赛滴神 | I34: 免费 | J34: 红币商店
C35: VLF Force 1 V10 | D35: VLF | E35: A | F35: 1.3 | G35: 3929 | H35: 仅次于腾风 | I35: 独家 | J35: 独家
C36: Lamborghini Aventador J | D36: AVJ | E36: A | F36: 1.5 | G36: 4002 | H36: 常驻黄金，上传奇滴神 | I36: 红币 | J36: 红币商店
C37: W Motors Lykan HyperSport | D37: 狼崽 | E37: S | F37: 1.3 | G37: 4083 | H37: 杯赛滴神 | I37: 免费 | J37: 红币商店
C38: Trion Nemesis | D38: 复仇 | E38: S | F38: 1.3 | G38: 4344 | H38: 小杰哥 | I38: 独家 | J38: 独家
C39: W Motors Fenyr SuperSport | D39: 狼王 | E39: S | F39: 1.3 | G39: 4479 | H39: 4275 | I39: 经典多人 | J39: 多人/氪金
A40: 活动快乐车 | B40: 不错的活动车 | C40: Lotus Elise Sprint 220 | D40: 小莲花 | E40: C | F40: 1.3 | G40: 2363 | H40: 搅屎棍 | J40: 红币商店
C41: Artega Scalo SuperErelletra | D41: Artega | E41: B | F41: 1.8 | G41: 3093 | H41: 电力加速 | J41: 紫币
C42: Ferrari J50 | D42: J50 | E42: B | F42: 1.3 | G42: 3229 | H42: 均衡性能 | J42: 红币商店
C43: Dodge Viper GTS | D43: A蛇 | E43: B | F43: 1.5 | G43: 3295 | H43: 均衡性能 | J43: 红币商店
C44: Ferrari 488 GTB | D44: 488 | E44: B | F44: 1.6 | G44: 3334 | H44: 均衡性能 | J44: 红币商店
C45: Mercedes-Benz SLR McLaren | D45: SLR | E45: B | F45: 1.7 | G45: 3389 | H45: 搅屎棍 | J45: 赛事
...

Sheet versionNoteAL
A1: _id | B1: releaseVersion | C1: note
A2: 0 | B2: 0.0 | C2: 尚未发布
A3: 1 | B3: 1.3 | C3: 开服
A4: 2 | B4: 1.4 | C4: 自私
A5: 3 | B5: 1.5 | C5: 统治
A6: 4 | B6: 1.6 | C6: 肥龙
A7: 5 | B7: 1.7 | C7: 塞纳
A8: 6 | B8: 1.8 | C8: 杰哥
A9: 7 | B9: 1.9 | C9: 自燃
A10: 8 | B10: 2.0 | C10: 电莲花
A11: 9 | B11: 2.1 | C11: C2
A12: 10 | B12: 2.2 | C12: 腾风
A13: 11 | B13: 2.3 | C13: 保时捷
... A47: 45 | B47: 5.8 | C47: 锐意争锋
